Watching for file changes with StatReloader
Exception in thread django-main-thread:
Traceback (most recent call last):
  File "/Users/adrianhalim/Documents/anotasi_image/anotasienv/lib/python3.13/site-packages/django/urls/resolvers.py", line 720, in url_patterns
    iter(patterns)
    ~~~~^^^^^^^^^^
TypeError: 'module' object is not iterable

The above exception was the direct cause of the following exception:

Traceback (most recent call last):
  File "/Library/Frameworks/Python.framework/Versions/3.13/lib/python3.13/threading.py", line 1041, in _bootstrap_inner
    self.run()
    ~~~~~~~~^^
  File "/Library/Frameworks/Python.framework/Versions/3.13/lib/python3.13/threading.py", line 992, in run
    self._target(*self._args, **self._kwargs)
    ~~~~~~~~~~~~^^^^^^^^^^^^^^^^^^^^^^^^^^^^^
  File "/Users/adrianhalim/Documents/anotasi_image/anotasienv/lib/python3.13/site-packages/django/utils/autoreload.py", line 64, in wrapper
    fn(*args, **kwargs)
    ~~^^^^^^^^^^^^^^^^^
  File "/Users/adrianhalim/Documents/anotasi_image/anotasienv/lib/python3.13/site-packages/django/core/management/commands/runserver.py", line 134, in inner_run
    self.check(display_num_errors=True)
    ~~~~~~~~~~^^^^^^^^^^^^^^^^^^^^^^^^^
  File "/Users/adrianhalim/Documents/anotasi_image/anotasienv/lib/python3.13/site-packages/django/core/management/base.py", line 486, in check
    all_issues = checks.run_checks(
        app_configs=app_configs,
    ...<2 lines>...
        databases=databases,
    )
  File "/Users/adrianhalim/Documents/anotasi_image/anotasienv/lib/python3.13/site-packages/django/core/checks/registry.py", line 88, in run_checks
    new_errors = check(app_configs=app_configs, databases=databases)
  File "/Users/adrianhalim/Documents/anotasi_image/anotasienv/lib/python3.13/site-packages/django/core/checks/urls.py", line 16, in check_url_config
    return check_resolver(resolver)
  File "/Users/adrianhalim/Documents/anotasi_image/anotasienv/lib/python3.13/site-packages/django/core/checks/urls.py", line 26, in check_resolver
    return check_method()
  File "/Users/adrianhalim/Documents/anotasi_image/anotasienv/lib/python3.13/site-packages/django/urls/resolvers.py", line 532, in check
    messages.extend(check_resolver(pattern))
                    ~~~~~~~~~~~~~~^^^^^^^^^
  File "/Users/adrianhalim/Documents/anotasi_image/anotasienv/lib/python3.13/site-packages/django/core/checks/urls.py", line 26, in check_resolver
    return check_method()
  File "/Users/adrianhalim/Documents/anotasi_image/anotasienv/lib/python3.13/site-packages/django/urls/resolvers.py", line 531, in check
    for pattern in self.url_patterns:
                   ^^^^^^^^^^^^^^^^^
  File "/Users/adrianhalim/Documents/anotasi_image/anotasienv/lib/python3.13/site-packages/django/utils/functional.py", line 47, in __get__
    res = instance.__dict__[self.name] = self.func(instance)
                                         ~~~~~~~~~^^^^^^^^^^
  File "/Users/adrianhalim/Documents/anotasi_image/anotasienv/lib/python3.13/site-packages/django/urls/resolvers.py", line 728, in url_patterns
    raise ImproperlyConfigured(msg.format(name=self.urlconf_name)) from e
django.core.exceptions.ImproperlyConfigured: The included URLconf '<module 'annotator.urls' from '/Users/adrianhalim/Documents/anotasi_image/Anotasi_Image/annotator/urls.py'>' does not appear to have any patterns in it. If you see the 'urlpatterns' variable with valid patterns in the file then the issue is probably caused by a circular import.
/Users/adrianhalim/Documents/anotasi_image/Anotasi_Image/annotator/urls.py changed, reloading.
Performing system checks...

Watching for file changes with StatReloader
System check identified some issues:

WARNINGS:
?: settings.ACCOUNT_AUTHENTICATION_METHOD is deprecated, use: settings.ACCOUNT_LOGIN_METHODS = {'email'}

System check identified 1 issue (0 silenced).
Performing system checks...

June 18, 2025 - 18:01:28
Django version 5.1.7, using settings 'Anotasi_Image.settings'
Starting development server at http://127.0.0.1:8003/
Quit the server with CONTROL-C.

